Workbook

Sheet Checklist
A1: Rediseño Curricular 2026 · Control de entregas de las subcomisiones
A2: Carrera de Contaduría Pública · Facultad de Ciencias Económicas y Financieras · Universidad Mayor de San Andrés
A4: Código | B4: Punto del índice | C4: Responsable docente | D4: Responsable estudiantil | E4: Estado | F4: Fecha de recepción | G4: Formato recibido | H4: Adaptado al formato | I4: Observaciones | J4: Entregable | K4: Información extraída de internet (verificar)
A5: 1. | B5: Identificación del programa/carrera | C5: Edwin Gutiérrez Zapana | D5: Alarcon Pablo Alejandro | E5: =IF(SUMPRODUCT(($J$6:$J$18=1)*($E$6:$E$18<>"No aplica"))=0,"No aplica",IF(SUMPRODUCT(($J$6:$J$18=1)*($E$6:$E$18="Entregado"))=SUMPRODUCT(($J$6:$J$18=1)*($E$6:$E$18<>"No aplica")),"Completo",IF(SUMPRODUCT(($J$6:$J$18=1)*($E$6:$E$18="Pendiente"))=SUMPRODUCT(($J$6:$J$18=1)*($E$6:$E$18<>"No aplica")),"Pendiente","En proceso"))) | F5: =SUMPRODUCT(($J$6:$J$18=1)*($E$6:$E$18="Entregado"))&" de "&SUMPRODUCT(($J$6:$J$18=1)*($E$6:$E$18<>"No aplica")) | G5: — | H5: — | J5: 0
A6: 1.1 | B6: Facultad | C6: Edwin Gutiérrez Zapana | D6: Alarcon Pablo Alejandro | E6: Entregado | F6: 46308 | G6: Word | H6: Sí | I6: Fuentes: Plan 2027 (1.1) y Plan 2024 (1.1, párrafo sobre autonomía y cogobierno, redacción corregida). La mención de las Carreras de Economía y Administración de Empresas sale del membrete de la Res. HCF 1057/2026. | J6: 1
A7: 1.2 | B7: Programa/carrera | C7: Edwin Gutiérrez Zapana | D7: Alarcon Pablo Alejandro | E7: Entregado | F7: 46308 | G7: Word | H7: Sí | I7: Fuentes: Plan 2027 (1.2) y Plan 2024 (resoluciones de cambio de nombre: HCU 186/2000, HC Carrera 142/2011, HCF 613/2011 y HCU 438/2012), que en el Plan 2024 estaban dentro de 1.4. Error: en el Plan 2024 el punto 1.2 estaba vacío. | J7: 1
A8: 1.3 | B8: Fecha de creación y Resolución HCU | C8: Edwin Gutiérrez Zapana | D8: Alarcon Pablo Alejandro | E8: Entregado | F8: 46308 | G8: Word | H8: Sí | I8: Fuentes: Plan 2027 (fecha de fundación 25/08/1970) y Plan 2024 (texto de la Res. HCU 057/1974). Error: el Plan 2027 presentaba la Res. HCU 057/1974 como resolución de creación de 1970 sin explicar que es de 1974; se aclaró. El Plan 2024 transcribía la resolución completa; se resumió. Si se desea el texto íntegro, va como anexo. Error en el Plan 2024: "CONTADOR GENERA" por "CONTADOR GENERAL". | J8: 1 | K8: Origen en el Congreso Interno de 1970 y contexto de la Revolución Universitaria de abril de 1970. Fuente: página de historia de la Carrera (contaduriapublica.umsa.bo/carrera). Resaltado en verde.
A9: 1.4 | B9: Resolución(es) HCU que aprobaron planes de estudio anteriores | C9: Edwin Gutiérrez Zapana | D9: Alarcon Pablo Alejandro | E9: Entregado | F9: 46308 | G9: Word | H9: Sí | I9: Fuentes: Plan 2027 (planes 1999 y 2013) y Plan 2024 (II Congreso Interno, Res. HCU 438/2012). Errores en el Plan 2027: "Nª025/2013" y "Nª524/2004" corregidos a "N.º", y faltaba la resolución del Plan 2024. Error en el Plan 2024: el subtítulo "1.4 Organigrama funcional..." pertenece al punto 2.6 y se excluyó. Verificar por qué el Plan 1999 se aprobó recién en 2004. CORRECCIÓN (diagnóstico 2026): el plan vigente es el Plan 2013, no el Plan 2024. Se agregaron las Resoluciones HCC 162/2012 y HCF 929/2012 del Plan 2013. CONFIRMAR qué ocurrió con el Plan 2024 (Res. HCU 233/2024): el documento del Plan 2024 y la web lo mencionan, pero el diagnóstico aprobado por la Res. HCF 1057/2026 diagnostica el Plan 2013 como vigente. | J9: 1 | K9: Plan de Estudios 2024 aprobado con Res. HCU N.º 233/2024; la fecha no se pudo confirmar. Fuente: Reglamentos Internos de la Carrera 2024 (contaduriapublica.umsa.bo/documentos/2024/07_2024). Resaltado en verde.
A10: 1.5 | B10: Grado académico terminal | C10: Edwin Gutiérrez Zapana | D10: Alarcon Pablo Alejandro | E10: Entregado | F10: 46308 | G10: Word | H10: Sí | I10: Fuentes: Plan 2027 (Licenciatura) y Plan 2024 (sección 3.17.7, cinco años y modalidad de graduación). Confirmar con la subcomisión del punto 4.3.5 que la duración se mantiene en cinco años en el Plan 2027. Error en el Plan 2024: numeración 3.17.7 arrastrada de otro documento. CORRECCIÓN (diagnóstico 2026): se confirman los cinco años y se agregan las 6.000 horas académicas del Plan 2013. | J10: 1
A11: 1.6 | B11: Grado(s) académico(s) intermedio(s) | C11: Edwin Gutiérrez Zapana | D11: Alarcon Pablo Alejandro | E11: Entregado | F11: 46308 | G11: Word | H11: Sí | I11: Fuentes: Plan 2027 (Res. HCU 290/2016) y Plan 2024 (3.17.7: Técnico Medio en segundo año y Art. 4 del Reglamento General de Títulos y Grados). CONFIRMAR si el Plan 2027 mantiene el Técnico Medio (Auxiliar en Contabilidad General); el Plan 2027 no lo menciona. Denominación: el Plan 2024 dice "Técnico Superior" y la Res. HCU 290/2016 dice "Técnico Universitario Superior"; se usó la de la resolución. El texto del Plan 2024 sobre el examen de grado técnico superior (3.17.6) corresponde al punto 5.4 y se reserva para ese punto. Errores en el Plan 2027: "Grado (s) académicos intermedios (s)" y espacios dentro de los paréntesis. CORRECCIÓN (diagnóstico 2026): se quitó la frase "El Plan de Estudios 2024 reconoce...", porque el plan vigente es el 2013. El Técnico Medio se mantiene sin atribuirlo a un plan y sigue PENDIENTE de confirmación. CONFIRMADO por la fuente terciaria (propuesta de plan de estudios, puntos de grados intermedios): mantiene el Técnico Medio (Auxiliar en Contabilidad General) al concluir el segundo año. Esa fuente usa "Técnico Superior en Contabilidad General"; se mantiene "Técnico Universitario Superior" por la Res. HCU 290/2016. Unificar. | J11: 1
A12: 1.7 | B12: Sede(s) | C12: Edwin Gutiérrez Zapana | D12: Alarcon Pablo Alejandro | E12: Entregado | F12: 46308 | G12: Word | H12: Sí | I12: Fuente: Plan 2027 (CRU Yungas-Chulumani y SUL Caranavi). Error en el Plan 2027: no mencionaba la sede central de La Paz; se agregó. Error en el Plan 2024: 1.7 vacío. Confirmar si existen otras sedes o programas desconcentrados vigentes. CORRECCIÓN (diagnóstico 2026, puntos 3.1 y 7.1): se agregaron los edificios de la sede central (Nava Morales, Av. Montes esq. Pando, y Monoblock Central, Av. Villazón) y los 104 inscritos de las sedes desconcentradas en 2025. | J12: 1
A13: 1.8 | B13: Diploma académico terminal | C13: Edwin Gutiérrez Zapana | D13: Alarcon Pablo Alejandro | E13: Entregado | F13: 46308 | G13: Word | H13: Sí | I13: Fuentes: Plan 2027 y Res. HCU 438/2012 (Plan 2024). Se quitó la mayúscula sostenida "TÍTULO ACADÉMICO: LICENCIADO...". Error en el Plan 2024: 1.8 vacío. | J13: 1
A14: 1.9 | B14: Diploma(s) académico(s) intermedio(s) | C14: Edwin Gutiérrez Zapana | D14: Alarcon Pablo Alejandro | E14: Entregado | F14: 46308 | G14: Word | H14: Sí | I14: Fuentes: Plan 2027 y Res. HCU 290/2016. Error en el Plan 2027: "Diploma ( s) académico (s) intermedio". Error en el Plan 2024: 1.9 vacío. | J14: 1
A15: 1.10 | B15: Título Profesional | C15: Edwin Gutiérrez Zapana | D15: Alarcon Pablo Alejandro | E15: Entregado | F15: 46308 | G15: Word | H15: Sí | I15: Fuentes: Plan 2027 y Res. HCU 438/2012. Error en el Plan 2024: 1.10 vacío. | J15: 1
A16: 1.11 | B16: Título(s) profesional(es) intermedio(s) | C16: Edwin Gutiérrez Zapana | D16: Alarcon Pablo Alejandro | E16: Entregado | F16: 46308 | G16: Word | H16: Sí | I16: Fuentes: Plan 2027 y Res. HCU 290/2016. Error en el Plan 2027: "Título (s) profesional (s) intermedios". Error en el Plan 2024: 1.11 vacío. | J16: 1
A17: 1.12 | B17: Modalidad(es) de docencia | C17: Edwin Gutiérrez Zapana | D17: Alarcon Pablo Alejandro | E17: Entregado | F17: 46308 | G17: Word | H17: Sí | I17: Error en el Plan 2027: respondía con las categorías docentes en lugar de la modalidad que pide el Art. 12 de la Res. HCU 032/2025; ese texto se traslada al punto 11.2. Texto nuevo respaldado por el diagnóstico 2026: modalidad presencial y régimen anual (punto 6.1), turnos diurno y nocturno (punto 3.1) y plataforma virtual de apoyo (punto 7.1 g). Ya no requiere confirmación. | J17: 1
A18: 1.13 | B18: Otras características | C18: Edwin Gutiérrez Zapana | D18: Alarcon Pablo Alejandro | E18: Entregado | F18: 46308 | G18: Word | H18: Sí | I18: El Plan 2027 no tenía 1.13 y en el Plan 2024 estaba vacío. Contenido elaborado con los documentos base: acreditación Res. 09/2015 VI Conferencia Nacional Extraordinaria (membrete de la Res. HCF 1057/2026), Res. HCU 032/2025 (Arts. 5 y 16), Res. HCF 1057/2026 y documento de Misión, Visión y Perfil 2026 (Reunión Sectorial III-XIII, Res. 07/2024, IES). Error en la Res. HCF 1057/2026: en Vistos cita "Proyecto de Resolución ... N.º 269/202" (año incompleto) y en Considerando "N° 269/202"; debe ser 269/2026. Verificar la vigencia de la acreditación de 2015. ACTUALIZADO con la fuente terciaria (Plan de Desarrollo 2026-2030): la acreditación de 2015 está por renovar; la reacreditación CEUB y ARCU-SUR son metas del plan. | J18: 1
A19: 2. | B19: Antecedentes | C19: Sin asignar | D19: Sin asignar | E19: =IF(SUMPRODUCT(($J$20:$J$26=1)*($E$20:$E$26<>"No aplica"))=0,"No aplica",IF(SUMPRODUCT(($J$20:$J$26=1)*($E$20:$E$26="Entregado"))=SUMPRODUCT(($J$20:$J$26=1)*($E$20:$E$26<>"No aplica")),"Completo",IF(SUMPRODUCT(($J$20:$J$26=1)*($E$20:$E$26="Pendiente"))=SUMPRODUCT(($J$20:$J$26=1)*($E$20:$E$26<>"No aplica")),"Pendiente","En proceso"))) | F19: =SUMPRODUCT(($J$20:$J$26=1)*($E$20:$E$26="Entregado"))&" de "&SUMPRODUCT(($J$20:$J$26=1)*($E$20:$E$26<>"No aplica")) | G19: — | H19: — | J19: 0
A20: 2.1 | B20: Datos generales del programa/carrera | C20: Sin asignar | D20: Sin asignar | E20: Entregado | F20: 46308 | G20: Word | H20: Sí | I20: Fuentes: documento de la comisión (copia del Plan 2024), punto 1 ya trabajado, Res. HCF 1057/2026 (Director de Carrera) y diagnóstico (población estudiantil, docentes y personal). Como el párrafo de la comisión repetía el texto del punto 1.1, se reemplazó por un cuadro de datos generales para evitar duplicidad. Error en el documento de la comisión: nota interna "(COPIA DEL DOCUMENTO 2024)" dentro del texto; se eliminó. Error en el Plan 2024: el título "1. ANTECEDENTES / 1.1 DATOS GENERALES" estaba repetido dentro de 2.1 y el punto incluía los objetivos de la Carrera, que corresponden a 2.4. CORRECCIÓN (diagnóstico 2026): plan vigente Plan 2013 (antes decía Plan 2024); se agregaron 43 asignaturas y 6.000 horas, turnos diurno y nocturno, edificios, 3.247 inscritos totales (3.143 en La Paz y 104 en sedes), composición por género, estudiantes que trabajan, 82 docentes en ejercicio y 79 ítems de auxiliares. | J20: 1
A21: 2.2 | B21: Misión, visión de la carrera | C21: Sin asignar | D21: Sin asignar | E21: Entregado | F21: 46308 | G21: Word | H21: Sí | I21: Fuente priorizada: fuente terciaria, documento 1 (visión y misión), igual al documento base Misión, Visión y Perfil 2026. Se agregó 2.2.3 Valores, tomado del mismo documento base, para mantener la coherencia. La visión y la misión se conservaron textuales por ser texto socializado; solo en Valores se cambió el paréntesis "(IA, Big Data y automatización)" por redacción corrida. El paréntesis "(IA y analítica de datos)" de la misión se mantiene; si se desea quitarlo, debe hacerse también en el documento base. Error en el documento de la comisión: nota interna "(copia del documento recién socializado)" en el título. El Plan 2024 tenía otra visión y misión, ya reemplazadas. | J21: 1
A22: 2.3 | B22: Plan de desarrollo de la carrera | C22: Sin asignar | D22: Sin asignar | E22: Entregado | F22: 46308 | G22: Word | H22: Sí | I22: Fuente: fuente terciaria (Plan Estratégico de Desarrollo Institucional 2026-2030 de la Carrera), reescrita y resumida. Se quitaron los rasgos de redacción de IA (guiones largos, paréntesis, términos como "refundación", "baluarte" o "arquitectura programática"); la visión, la misión y los valores no se repitieron porque ya están en 2.2. Se armonizaron los cuatro ejes del plan con las cuatro áreas del PEI UMSA y con los seis ejes de los objetivos (2.4). ERRORES EN LA FUENTE: (1) atribuye al Art. 8 de la Res. HCU 032/2025 el "modelo humanista, flexible... por competencias", pero el Art. 8 trata la estructura de contenidos; se citó el Art. 12; (2) presenta como "brecha en inglés del 89 %" un dato que el diagnóstico registra como el 89 % de estudiantes que ve la demanda de idiomas y tecnología como amenaza; se corrigió; (3) líneas base sin respaldo, derivadas de otros porcentajes: inglés "11 %" (100 - 89), laboratorios "7 %" (100 - 93, que es una brecha de egresados, no de laboratorios), pasantías "12 %" y docentes capacitados "15 %" sin fuente; se reemplazaron por "Por establecer"; (4) unidades responsables que no existen en el organigrama (Jefatura de Estudios, Departamento de Idiomas, Unidad de Calidad Académica, Jefatura de Laboratorios); se asignaron a la Dirección de Carrera; (5) el nombre del plan es inconsistente: "Plan de Estudios CPA 2026" en la fuente y "Plan 2027" en otros documentos; (6) cita "ISSA 5000"; en español corresponde NIAS 5000. | J22: 1 | K22: PEI UMSA 2021-2025 con visión al 2030, Res. HCU 355/2023 (se mantiene en verde).
A23: 2.4 | B23: Objetivos del programa/carrera | C23: Sin asignar | D23: Sin asignar | E23: Entregado | F23: 46308 | G23: Word | H23: Sí | I23: Fuente priorizada: fuente terciaria, documento 2 (2.4.1, seis ejes), que es la versión más reciente: incluye "Código Internacional de Ética", "pasantías preprofesionales obligatorias" y "la incertidumbre". Cambios: "analítica de datos (Big Data)" se redactó "analítica de datos masivos", se completó el nombre del IESBA (Consejo de Normas Internacionales de Ética para Contadores) y se pasaron los rótulos a minúscula inicial. Error en el documento 2 de la fuente terciaria: las seis viñetas estaban dentro de un solo ítem; se separaron como incisos a-f. DIFERENCIA con el documento base Misión, Visión y Perfil 2026 (punto 3) y con el documento 1 de la fuente terciaria: estos dicen "pre-profesionales" sin "obligatorias" y "Código de Ética"; conviene actualizar el documento base para que coincida. Error en el documento 1 de la fuente terciaria: "pasantías pre-profesionales" con guion. | J23: 1
A24: 2.5 | B24: Características del programa/carrera | C24: Sin asignar | D24: Sin asignar | E24: Entregado | F24: 46308 | G24: Word | H24: Sí | I24: Fuente: Plan 2024 (1.3 Reseña histórica y 1.5 Unidades académicas); la comisión no incluyó este punto. Correcciones al Plan 2024: "culmino" por "culminó"; oración incompleta "El nuevo rol protagónico... que culmino con el golpe de estado", reescrita; "Carrera de Contaduría Auditoria ahora Contaduría Pública" corregido; frase colgante "Razón por la cual se dicta la siguiente resolución:" sin resolución, reemplazada por la remisión al punto 1.2; tildes faltantes en Auditoría y Maestría; título "2. Justificación del Diseño" fuera de lugar, eliminado. ACTUALIZAR las versiones de los programas de postgrado (datos del Plan 2024) y el estado del doctorado. La lista de reglamentos del Plan 2024 se traslada al punto 13.1. CORRECCIÓN (diagnóstico 2026, puntos 9.1 y 10): se reemplazó la lista de postgrado del Plan 2024, que tenía versiones desactualizadas, por los programas vigentes y los que se implementan en 2026; nombre completo del doctorado; datos del Instituto (320 h/mes, Director acéfalo desde 2022, sin personal administrativo). Error en el diagnóstico: "Diplomado en Auditoría Forense Virtual" se redactó "en modalidad virtual"; "esta de cargo" debe ser "está a cargo". | J24: 1
A25: 2.6 | B25: Organigrama del programa/carrera | C25: Sin asignar | D25: Sin asignar | E25: Entregado | F25: 46308 | G25: Word | H25: Sí | I25: Fuentes: organigrama (imagen) y descripción del documento de la comisión, igual al Plan 2024, y 2.6.1 Plantel administrativo del diagnóstico. Redacción ajustada y sin repeticiones. ERRORES EN LA IMAGEN DEL ORGANIGRAMA (no se pueden corregir en el Word, hay que rehacer la imagen): "KARDIXTA" por "KARDEXISTA", "TRANCRIPTOR" por "TRANSCRIPTOR"; dice "JEFATURA DE CARRERA" mientras el texto dice "Dirección de Carrera"; muestra la Unidad de Postgrado al mismo nivel que el Instituto, mientras el texto dice que depende del Instituto. Incoherencia: el texto del Plan 2024 sobre la Jefatura de Dirección hablaba de "dos secretarias, un profesional contable...", que no coincide con las tablas de personal; se redactó sin cantidades. En las tablas: "Kardixtas I" corregido a "Kardexista I", "Centro de Computo" a "Cómputo", "(item)" a "ítem", y se unificaron las filas repetidas de porteros y becarios. Nombre del Instituto unificado según la Res. HCU 457/2004. CORRECCIÓN POSTERIOR: la sigla PETAEG del diagnóstico se unificó a PETAENG (Plan Excepcional de Titulación para Antiguos Estudiantes No Graduados), como en la comisión y el Plan 2024. | J25: 1
A26: 2.7 | B26: Estadísticas del programa/carrera | C26: Sin asignar | D26: Sin asignar | E26: Entregado | F26: 46308 | G26: Word | H26: Sí | I26: Fuente: estadísticas del diagnóstico 2021-2025 (documento de la comisión), que reemplazan a las del Plan 2024. ERRORES CORREGIDOS: (1) se decía que los inscritos "se incrementaron en 378 equivalentes al 13,32 %", dato copiado del Plan 2024 (periodo 2019-2023); con los datos 2021-2025 bajan de 3.152 a 3.143 (-0,29 %); (2) 1.140/4.283 = 26,62 %, no 26,61 %; (3) en el Cuadro 11 la fila Paralelos repetía el promedio en las columnas PEIPAP; se reorganizó el cuadro; (4) el texto del Cuadro 11 decía "relativamente estable" y a la vez "se ha incrementado significativamente"; se aclaró que crece el total de inscripciones y no el promedio; (5) la fuente "Sistema de Registro Universitario -- SSA y Sistema de Seguimiento Académico - SSA" repetía la sigla. Se calculó y agregó que el examen de grado representa el 69,7 % de los titulados 2021-2025. INCOHERENCIAS POR ACLARAR con la comisión: (a) el Cuadro 5 da 82 docentes y los Cuadros 4 y 7 dan 183; se interpretó 183 como designaciones y no personas; la nota "El total de docentes corresponde a materias de 32 Hrs" no es clara y se omitió; (b) matriculados 2023: el diagnóstico dice 4.447 y el Plan 2024 dice 4.385; (c) titulados 2021: DSIE da 441 y Kárdex (Plan 2024) daba 514; (d) CEIPAP 2023: 22.636 frente a 22.641 en el Plan 2024. Se renumeraron los cuadros del 1 al 11 dentro del punto 2. CORRECCIÓN (diagnóstico 2026, puntos 3.1, 3.2, 3.3 y 11): se agregaron los inscritos totales, la composición por género, los estudiantes trabajadores, los nuevos inscritos 2023-2025, los estudiantes con 7 a 9 años de permanencia y las auxiliaturas. El diagnóstico tiene los mismos errores de los Cuadros 9 a 11 señalados arriba: "se incrementaron en 378, 13,32 %", 26,61 % y la fuente con la sigla SSA repetida. Además, en el punto 6.4 d) habla de "183 docentes disponibles" y en el Cuadro 6 de 82 docentes. | J26: 1
A27: 3. | B27: Justificación de la innovación curricular (solo para niveles de diseño, rediseño y ajustes) | C27: Alberto Mendoza Mendoza | D27: Ayrton Javier Quisbert Fernandez | E27: =IF(SUMPRODUCT(($J$28:$J$32=1)*($E$28:$E$32<>"No aplica"))=0,"No aplica",IF(SUMPRODUCT(($J$28:$J$32=1)*($E$28:$E$32="Entregado"))=SUMPRODUCT(($J$28:$J$32=1)*($E$28:$E$32<>"No aplica")),"Completo",IF(SUMPRODUCT(($J$28:$J$32=1)*($E$28:$E$32="Pendiente"))=SUMPRODUCT(($J$28:$J$32=1)*($E$28:$E$32<>"No aplica")),"Pendiente","En proceso"))) | F27: =SUMPRODUCT(($J$28:$J$32=1)*($E$28:$E$32="Entregado"))&" de "&SUMPRODUCT(($J$28:$J$32=1)*($E$28:$E$32<>"No aplica")) | G27: — | H27: — | J27: 0
A28: 3.1 | B28: Análisis de resultados obtenidos con anteriores planes de estudio (descripción estadística y cualitativa) | C28: Alberto Mendoza Mendoza | D28: Ayrton Javier Quisbert Fernandez | E28: Entregado | F28: 46308 | G28: Word | H28: Sí | I28: Fuente principal: documento de la comisión (3.1), con el Plan 2024 y el diagnóstico 2026 como respaldo. ACTUALIZACIÓN: la comisión usaba series 2018-2023 (Centro de Cómputo y Kárdex) y pedía actualizarlas; se reemplazaron por las del diagnóstico 2026: matrícula 2021-2025, titulados 2021-2025 DSIE (examen de grado 69,73 %, trabajo dirigido 14,58 %, tesis 0,16 %), dedicación docente 2026 (2 cargas de tiempo completo de 108, 58,33 % con carga mínima), interinos en Atestación 73,33 % y 106 estudiantes por paralelo en 2026. Se quitó la afirmación "concentración creciente en el examen", porque con los datos 2021-2025 el examen baja de 78,2 % a 68,6 %. Se mantuvo la observación técnica de la comisión sobre los porcentajes erróneos del Cuadro 4 del Documento 2013. Error de la comisión: el Cuadro 2 decía "Desarrollo y Comportamiento Organizacional"; el diagnóstico dice "Desarrollo Organizacional y Comportamiento Organizacional". "Álgebra y Programación Lineales" se corrigió a "Lineal". Del diagnóstico quedan pendientes los errores anotados antes (caída de matrícula con tres cifras distintas, entre otros); no se usaron esas cifras. | J28: 1
A29: 3.2 | B29: Análisis de las políticas y normas (internacionales, nacionales y universitarias) | C29: Alberto Mendoza Mendoza | D29: Ayrton Javier Quisbert Fernandez | E29: Entregado | F29: 46308 | G29: Word | H29: Sí | I29: Fuentes: comisión (3.2, completo) y fuente terciaria (3.2.1: procedimiento con las Res. HCF 1057/2026 y 1126/2026). INCOHERENCIA: la fuente terciaria dice que la Asamblea se realizó el 8/09/2026, pero la Res. HCF 1057/2026 la convoca para el 4/09/2026; se dejó la fecha de la resolución. VERIFICAR el número y la fecha de la Res. HCF 1126/2026 (solo figura en la fuente terciaria). Terminología unificada: la comisión usa "NIE" y la fuente terciaria "IES"; se usa IES en todo el documento. ISSA 5000 se nombra "NIAS 5000" en español (la comisión decía NIEA 5000). Se eliminó el Cuadro 16 de la comisión (NIE e implicancia), porque se fusionó con la tabla de la fuente terciaria en el Cuadro 30 (3.5.4). | J29: 1
A30: 3.3 | B30: Análisis del contexto económico, estudio de mercado laboral e inserción laboral | C30: Alberto Mendoza Mendoza | D30: Ayrton Javier Quisbert Fernandez | E30: Entregado | F30: 46308 | G30: Word | H30: Sí | I30: Fuente: comisión (3.3) y verificación directa en el informe Ipsos CIESMORI. CIFRAS VERIFICADAS EN IPSOS (láminas 18, 19, 38 y 39): Contaduría tiene 52 % dependientes, 31 % independientes o consultores y 14 % desempleados; el 41 % que usan el documento de Misión, Visión y Perfil, el diagnóstico y el Plan de Desarrollo corresponde a Economía. La "brecha del 93 %" de esos documentos es en realidad el porcentaje de egresados que considera "totalmente necesarias" las habilidades tecnológicas básicas; la brecha real es de 43 pp (98 % necesaria frente a 55 % aplicada) y de 51 pp en emergentes. Lo mismo ocurre con "gestión del tiempo 81 %" y "pensamiento crítico 78 %", que son valores de "totalmente necesaria"; las brechas son de 35 y 25 pp. Se corrigió también el punto 2.3. PENDIENTE: la propia comisión pide contrastar con los documentos originales las cifras macroeconómicas de 2026 (FMI, Banco Mundial, INE, BCB), que tomó de la prensa. | J30: 1
A31: 3.4 | B31: Análisis del contexto de cambios y tendencias de la ciencia y tecnología a nivel global | C31: Humberto Quintanilla Muñoz | D31: Beymar Adalid Paucara Marquez | E31: Entregado | F31: 46308 | G31: Word | H31: Sí | I31: Fuente: comisión (3.4). Solo cambió la redacción: se quitaron guiones largos y negritas excesivas, y los términos en inglés se tradujeron cuando hay equivalente (RPA: automatización robótica de procesos; ERP: sistemas de gestión empresarial). | J31: 1
A32: 3.5 | B32: Contextualización de la oferta curricular en la realidad nacional e internacional | C32: Humberto Quintanilla Muñoz | D32: Beymar Adalid Paucara Marquez | E32: Entregado | F32: 46308 | G32: Word | H32: Sí | I32: Fuentes: comisión (3.5) y fuente terciaria (3.5.1, tabla IES 1 a IES 8, fusionada en el Cuadro 30). ERROR GRAVE DE LA COMISIÓN CORREGIDO: afirmaba que la UMSA otorga el título de "Auditor Financiero" y que es la única del SUB que no otorga el de Contador Público Autorizado. Desde la Res. HCU 438/2012 el título en provisión nacional es Contador Público Autorizado (punto 1.10). Se corrigieron los Cuadros 17, 29 y 31 y el texto: lo desalineado es el perfil de egreso, no el título. Error de la comisión: en el Cuadro 31, "Salidas intermedias: Ausentes" en el Plan 2013; existe el Técnico Universitario Superior (Res. HCU 290/2016). Se agregó el dato del rango de horas SUB (4.500 a 6.000) del diagnóstico. Se trasladaron al punto 11 (implementación) y al 16.2 los Cuadros 33 a 35 de la comisión (paralelos requeridos, fases de implementación y riesgos), y se omitió el Cuadro 36 (verificación de cumplimiento del Art. 12), que es control interno. La comisión numeraba "3.6" la síntesis; el índice no tiene 3.6, así que pasó a 3.5.5. | J32: 1
A33: 4. | B33: Aspectos académicos | C33: Freddy Huanca Mamani | D33: Katherin Fabiola Ali Quispe | E33: =IF(SUMPRODUCT(($J$34:$J$71=1)*($E$34:$E$71<>"No aplica"))=0,"No aplica",IF(SUMPRODUCT(($J$34:$J$71=1)*($E$34:$E$71="Entregado"))=SUMPRODUCT(($J$34:$J$71=1)*($E$34:$E$71<>"No aplica")),"Completo",IF(SUMPRODUCT(($J$34:$J$71=1)*($E$34:$E$71="Pendiente"))=SUMPRODUCT(($J$34:$J$71=1)*($E$34:$E$71<>"No aplica")),"Pendiente","En proceso"))) | F33: =SUMPRODUCT(($J$34:$J$71=1)*($E$34:$E$71="Entregado"))&" de "&SUMPRODUCT(($J$34:$J$71=1)*($E$34:$E$71<>"No aplica")) | G33: — | H33: — | J33: 0
A34: 4.1 | B34: Fundamentos curriculares | C34: Freddy Huanca Mamani | D34: Katherin Fabiola Ali Quispe | E34: =IF(SUMPRODUCT(($J$35:$J$39=1)*($E$35:$E$39<>"No aplica"))=0,"No aplica",IF(SUMPRODUCT(($J$35:$J$39=1)*($E$35:$E$39="Entregado"))=SUMPRODUCT(($J$35:$J$39=1)*($E$35:$E$39<>"No aplica")),"Completo",IF(SUMPRODUCT(($J$35:$J$39=1)*($E$35:$E$39="Pendiente"))=SUMPRODUCT(($J$35:$J$39=1)*($E$35:$E$39<>"No aplica")),"Pendiente","En proceso"))) | F34: =SUMPRODUCT(($J$35:$J$39=1)*($E$35:$E$39="Entregado"))&" de "&SUMPRODUCT(($J$35:$J$39=1)*($E$35:$E$39<>"No aplica")) | G34: — | H34: — | J34: 0
A35: 4.1.1 | B35: Fundamentos epistemológicos | C35: Freddy Huanca Mamani | D35: Katherin Fabiola Ali Quispe | E35: Entregado | F35: 46308 | G35: Word | H35: Sí | I35: Fuente: fuente terciaria (Partes Complementarias y 4.1). Se agregó la ampliación epistemológica del objeto (sostenibilidad), tomada del punto 3.4 de la comisión. Error en la fuente: "entorno organización dinámico" por "organizacional". | J35: 1
A36: 4.1.2 | B36: Fundamentos sociológicos antropológicos | C36: Freddy Huanca Mamani | D36: Katherin Fabiola Ali Quispe | E36: Entregado | F36: 46308 | G36: Word | H36: Sí | I36: Fuente: fuente terciaria, con las cifras corregidas: "brecha del 93 %" por 43 y 51 pp (ver 3.3); "la principal barrera (25 %)" por "la segunda barrera" (la primera son las habilidades blandas, 26 %); y "el 88 % exige pasantías e inglés" se separó: 88 % pasantías y 89 % ven como amenaza la demanda de idiomas y tecnología. Se agregó el contexto sociocultural (modelo económico plural, informalidad, estudiante trabajador, 56 % mujeres) del diagnóstico y del punto 3. | J36: 1
A37: 4.1.3 | B37: Fundamentos psicológicos | C37: Jorge Cespedes Esteves | D37: Taiz Alejandra Cano Chuyma | E37: Entregado | F37: 46308 | G37: Word | H37: Sí | I37: Fuentes: fuente terciaria (roles del docente y del estudiante) y Plan 2024 (pedagogía dialogante constructivista, resumida). La fuente terciaria ponía como "fundamentos psicológicos" solo el marco normativo y los roles, sin fundamento psicológico; se agregó el enfoque constructivista y el aprendizaje significativo del Plan 2024. | J37: 1
A38: 4.1.4 | B38: Fundamentos educativos | C38: Jorge Cespedes Esteves | D38: Taiz Alejandra Cano Chuyma | E38: Entregado | F38: 46308 | G38: Word | H38: Sí | I38: Fuente: fuente terciaria. Para no duplicar, la tabla IES 1 a IES 8 queda solo en el punto 3.5.4 (Cuadro 30) y aquí se la remite. Error en la fuente: la tabla "Saber Conocer" tenía una fila suelta "Integrado" y la abreviatura "CGE NIA" sin separar. | J38: 1
A39: 4.1.5 | B39: Fundamentos axiológicos | C39: Jorge Cespedes Esteves | D39: Taiz Alejandra Cano Chuyma | E39: Entregado | F39: 46308 | G39: Word | H39: Sí | I39: Fuentes: fuente terciaria (4.1.5) y Plan de Desarrollo (tabla de impacto de los valores en el perfil). Para no repetir la definición de los valores de 2.2.3, aquí se usa la tabla de impacto. Se quitaron expresiones como "compromiso inquebrantable". | J39: 1
A40: 4.2 | B40: Referentes disciplinares | C40: Hinojosa | D40: Melany Sarah Chavez Condori | E40: =IF(SUMPRODUCT(($J$41:$J$47=1)*($E$41:$E$47<>"No aplica"))=0,"No aplica",IF(SUMPRODUCT(($J$41:$J$47=1)*($E$41:$E$47="Entregado"))=SUMPRODUCT(($J$41:$J$47=1)*($E$41:$E$47<>"No aplica")),"Completo",IF(SUMPRODUCT(($J$41:$J$47=1)*($E$41:$E$47="Pendiente"))=SUMPRODUCT(($J$41:$J$47=1)*($E$41:$E$47<>"No aplica")),"Pendiente","En proceso"))) | F40: =SUMPRODUCT(($J$41:$J$47=1)*($E$41:$E$47="Entregado"))&" de "&SUMPRODUCT(($J$41:$J$47=1)*($E$41:$E$47<>"No aplica")) | G40: — | H40: — | I40: Revisión final: "En conclusión" se cambió por "Así" para evitar una muletilla propia de textos generados. | J40: 0
A41: 4.2.1 | B41: Problemas que serán abordados por el profesional | C41: Hinojosa | D41: Melany Sarah Chavez Condori | E41: Entregado | F41: 46308 | G41: Word | H41: Sí | I41: Fuente: fuente terciaria (Partes Complementarias 4.2.1). Corregido "brecha digital (93 %)" y "ISSA 5000 / NIEA 3000" (se usa NIAS 5000). Se agregaron la informalidad y la recesión del punto 3.3. | J41: 1
...

Sheet Resumen
A1: Resumen de avance por punto
A2: Se calcula solo con los ítems entregables de la hoja Checklist. Los ítems marcados «No aplica» no cuentan en el total ni en el avance.
A4: Punto | B4: Título | C4: Ítems | D4: Entregados | E4: Parciales | F4: Observados | G4: Pendientes | H4: Avance | I4: No aplica
A5: 1 | B5: Identificación del programa/carrera | C5: =COUNTIFS(Checklist!$A$5:$A$137,"1.*",Checklist!$J$5:$J$137,1,Checklist!$E$5:$E$137,"<>No aplica") | D5: =COUNTIFS(Checklist!$A$5:$A$137,"1.*",Checklist!$J$5:$J$137,1,Checklist!$E$5:$E$137,"Entregado") | E5: =COUNTIFS(Checklist!$A$5:$A$137,"1.*",Checklist!$J$5:$J$137,1,Checklist!$E$5:$E$137,"Parcial") | F5: =COUNTIFS(Checklist!$A$5:$A$137,"1.*",Checklist!$J$5:$J$137,1,Checklist!$E$5:$E$137,"Observado") | G5: =COUNTIFS(Checklist!$A$5:$A$137,"1.*",Checklist!$J$5:$J$137,1,Checklist!$E$5:$E$137,"Pendiente") | H5: =IF(C5=0,IF(I5>0,1,0),D5/C5) | I5: =COUNTIFS(Checklist!$A$5:$A$137,"1.*",Checklist!$J$5:$J$137,1,Checklist!$E$5:$E$137,"No aplica")
A6: 2 | B6: Antecedentes | C6: =COUNTIFS(Checklist!$A$5:$A$137,"2.*",Checklist!$J$5:$J$137,1,Checklist!$E$5:$E$137,"<>No aplica") | D6: =COUNTIFS(Checklist!$A$5:$A$137,"2.*",Checklist!$J$5:$J$137,1,Checklist!$E$5:$E$137,"Entregado") | E6: =COUNTIFS(Checklist!$A$5:$A$137,"2.*",Checklist!$J$5:$J$137,1,Checklist!$E$5:$E$137,"Parcial") | F6: =COUNTIFS(Checklist!$A$5:$A$137,"2.*",Checklist!$J$5:$J$137,1,Checklist!$E$5:$E$137,"Observado") | G6: =COUNTIFS(Checklist!$A$5:$A$137,"2.*",Checklist!$J$5:$J$137,1,Checklist!$E$5:$E$137,"Pendiente") | H6: =IF(C6=0,IF(I6>0,1,0),D6/C6) | I6: =COUNTIFS(Checklist!$A$5:$A$137,"2.*",Checklist!$J$5:$J$137,1,Checklist!$E$5:$E$137,"No aplica")
A7: 3 | B7: Justificación de la innovación curricular (solo para niveles de diseño, rediseño y ajustes) | C7: =COUNTIFS(Checklist!$A$5:$A$137,"3.*",Checklist!$J$5:$J$137,1,Checklist!$E$5:$E$137,"<>No aplica") | D7: =COUNTIFS(Checklist!$A$5:$A$137,"3.*",Checklist!$J$5:$J$137,1,Checklist!$E$5:$E$137,"Entregado") | E7: =COUNTIFS(Checklist!$A$5:$A$137,"3.*",Checklist!$J$5:$J$137,1,Checklist!$E$5:$E$137,"Parcial") | F7: =COUNTIFS(Checklist!$A$5:$A$137,"3.*",Checklist!$J$5:$J$137,1,Checklist!$E$5:$E$137,"Observado") | G7: =COUNTIFS(Checklist!$A$5:$A$137,"3.*",Checklist!$J$5:$J$137,1,Checklist!$E$5:$E$137,"Pendiente") | H7: =IF(C7=0,IF(I7>0,1,0),D7/C7) | I7: =COUNTIFS(Checklist!$A$5:$A$137,"3.*",Checklist!$J$5:$J$137,1,Checklist!$E$5:$E$137,"No aplica")
A8: 4 | B8: Aspectos académicos | C8: =COUNTIFS(Checklist!$A$5:$A$137,"4.*",Checklist!$J$5:$J$137,1,Checklist!$E$5:$E$137,"<>No aplica") | D8: =COUNTIFS(Checklist!$A$5:$A$137,"4.*",Checklist!$J$5:$J$137,1,Checklist!$E$5:$E$137,"Entregado") | E8: =COUNTIFS(Checklist!$A$5:$A$137,"4.*",Checklist!$J$5:$J$137,1,Checklist!$E$5:$E$137,"Parcial") | F8: =COUNTIFS(Checklist!$A$5:$A$137,"4.*",Checklist!$J$5:$J$137,1,Checklist!$E$5:$E$137,"Observado") | G8: =COUNTIFS(Checklist!$A$5:$A$137,"4.*",Checklist!$J$5:$J$137,1,Checklist!$E$5:$E$137,"Pendiente") | H8: =IF(C8=0,IF(I8>0,1,0),D8/C8) | I8: =COUNTIFS(Checklist!$A$5:$A$137,"4.*",Checklist!$J$5:$J$137,1,Checklist!$E$5:$E$137,"No aplica")
A9: 5 | B9: Admisión, promoción y graduación | C9: =COUNTIFS(Checklist!$A$5:$A$137,"5.*",Checklist!$J$5:$J$137,1,Checklist!$E$5:$E$137,"<>No aplica") | D9: =COUNTIFS(Checklist!$A$5:$A$137,"5.*",Checklist!$J$5:$J$137,1,Checklist!$E$5:$E$137,"Entregado") | E9: =COUNTIFS(Checklist!$A$5:$A$137,"5.*",Checklist!$J$5:$J$137,1,Checklist!$E$5:$E$137,"Parcial") | F9: =COUNTIFS(Checklist!$A$5:$A$137,"5.*",Checklist!$J$5:$J$137,1,Checklist!$E$5:$E$137,"Observado") | G9: =COUNTIFS(Checklist!$A$5:$A$137,"5.*",Checklist!$J$5:$J$137,1,Checklist!$E$5:$E$137,"Pendiente") | H9: =IF(C9=0,IF(I9>0,1,0),D9/C9) | I9: =COUNTIFS(Checklist!$A$5:$A$137,"5.*",Checklist!$J$5:$J$137,1,Checklist!$E$5:$E$137,"No aplica")
A10: 6 | B10: Investigación (articulada con los institutos o unidades de investigación relacionados con la carrera/programa) | C10: =COUNTIFS(Checklist!$A$5:$A$137,"6.*",Checklist!$J$5:$J$137,1,Checklist!$E$5:$E$137,"<>No aplica") | D10: =COUNTIFS(Checklist!$A$5:$A$137,"6.*",Checklist!$J$5:$J$137,1,Checklist!$E$5:$E$137,"Entregado") | E10: =COUNTIFS(Checklist!$A$5:$A$137,"6.*",Checklist!$J$5:$J$137,1,Checklist!$E$5:$E$137,"Parcial") | F10: =COUNTIFS(Checklist!$A$5:$A$137,"6.*",Checklist!$J$5:$J$137,1,Checklist!$E$5:$E$137,"Observado") | G10: =COUNTIFS(Checklist!$A$5:$A$137,"6.*",Checklist!$J$5:$J$137,1,Checklist!$E$5:$E$137,"Pendiente") | H10: =IF(C10=0,IF(I10>0,1,0),D10/C10) | I10: =COUNTIFS(Checklist!$A$5:$A$137,"6.*",Checklist!$J$5:$J$137,1,Checklist!$E$5:$E$137,"No aplica")
A11: 7 | B11: Interacción social y extensión universitaria | C11: =COUNTIFS(Checklist!$A$5:$A$137,"7.*",Checklist!$J$5:$J$137,1,Checklist!$E$5:$E$137,"<>No aplica") | D11: =COUNTIFS(Checklist!$A$5:$A$137,"7.*",Checklist!$J$5:$J$137,1,Checklist!$E$5:$E$137,"Entregado") | E11: =COUNTIFS(Checklist!$A$5:$A$137,"7.*",Checklist!$J$5:$J$137,1,Checklist!$E$5:$E$137,"Parcial") | F11: =COUNTIFS(Checklist!$A$5:$A$137,"7.*",Checklist!$J$5:$J$137,1,Checklist!$E$5:$E$137,"Observado") | G11: =COUNTIFS(Checklist!$A$5:$A$137,"7.*",Checklist!$J$5:$J$137,1,Checklist!$E$5:$E$137,"Pendiente") | H11: =IF(C11=0,IF(I11>0,1,0),D11/C11) | I11: =COUNTIFS(Checklist!$A$5:$A$137,"7.*",Checklist!$J$5:$J$137,1,Checklist!$E$5:$E$137,"No aplica")
A12: 8 | B12: Organización del proceso curricular | C12: =COUNTIFS(Checklist!$A$5:$A$137,"8.*",Checklist!$J$5:$J$137,1,Checklist!$E$5:$E$137,"<>No aplica") | D12: =COUNTIFS(Checklist!$A$5:$A$137,"8.*",Checklist!$J$5:$J$137,1,Checklist!$E$5:$E$137,"Entregado") | E12: =COUNTIFS(Checklist!$A$5:$A$137,"8.*",Checklist!$J$5:$J$137,1,Checklist!$E$5:$E$137,"Parcial") | F12: =COUNTIFS(Checklist!$A$5:$A$137,"8.*",Checklist!$J$5:$J$137,1,Checklist!$E$5:$E$137,"Observado") | G12: =COUNTIFS(Checklist!$A$5:$A$137,"8.*",Checklist!$J$5:$J$137,1,Checklist!$E$5:$E$137,"Pendiente") | H12: =IF(C12=0,IF(I12>0,1,0),D12/C12) | I12: =COUNTIFS(Checklist!$A$5:$A$137,"8.*",Checklist!$J$5:$J$137,1,Checklist!$E$5:$E$137,"No aplica")
A13: 9 | B13: Material Bibliográfico | C13: =COUNTIFS(Checklist!$A$5:$A$137,"9.*",Checklist!$J$5:$J$137,1,Checklist!$E$5:$E$137,"<>No aplica") | D13: =COUNTIFS(Checklist!$A$5:$A$137,"9.*",Checklist!$J$5:$J$137,1,Checklist!$E$5:$E$137,"Entregado") | E13: =COUNTIFS(Checklist!$A$5:$A$137,"9.*",Checklist!$J$5:$J$137,1,Checklist!$E$5:$E$137,"Parcial") | F13: =COUNTIFS(Checklist!$A$5:$A$137,"9.*",Checklist!$J$5:$J$137,1,Checklist!$E$5:$E$137,"Observado") | G13: =COUNTIFS(Checklist!$A$5:$A$137,"9.*",Checklist!$J$5:$J$137,1,Checklist!$E$5:$E$137,"Pendiente") | H13: =IF(C13=0,IF(I13>0,1,0),D13/C13) | I13: =COUNTIFS(Checklist!$A$5:$A$137,"9.*",Checklist!$J$5:$J$137,1,Checklist!$E$5:$E$137,"No aplica")
A14: 10 | B14: Recursos educativos | C14: =COUNTIFS(Checklist!$A$5:$A$137,"10.*",Checklist!$J$5:$J$137,1,Checklist!$E$5:$E$137,"<>No aplica") | D14: =COUNTIFS(Checklist!$A$5:$A$137,"10.*",Checklist!$J$5:$J$137,1,Checklist!$E$5:$E$137,"Entregado") | E14: =COUNTIFS(Checklist!$A$5:$A$137,"10.*",Checklist!$J$5:$J$137,1,Checklist!$E$5:$E$137,"Parcial") | F14: =COUNTIFS(Checklist!$A$5:$A$137,"10.*",Checklist!$J$5:$J$137,1,Checklist!$E$5:$E$137,"Observado") | G14: =COUNTIFS(Checklist!$A$5:$A$137,"10.*",Checklist!$J$5:$J$137,1,Checklist!$E$5:$E$137,"Pendiente") | H14: =IF(C14=0,IF(I14>0,1,0),D14/C14) | I14: =COUNTIFS(Checklist!$A$5:$A$137,"10.*",Checklist!$J$5:$J$137,1,Checklist!$E$5:$E$137,"No aplica")
A15: 11 | B15: Implementación del proyecto curricular | C15: =COUNTIFS(Checklist!$A$5:$A$137,"11.*",Checklist!$J$5:$J$137,1,Checklist!$E$5:$E$137,"<>No aplica") | D15: =COUNTIFS(Checklist!$A$5:$A$137,"11.*",Checklist!$J$5:$J$137,1,Checklist!$E$5:$E$137,"Entregado") | E15: =COUNTIFS(Checklist!$A$5:$A$137,"11.*",Checklist!$J$5:$J$137,1,Checklist!$E$5:$E$137,"Parcial") | F15: =COUNTIFS(Checklist!$A$5:$A$137,"11.*",Checklist!$J$5:$J$137,1,Checklist!$E$5:$E$137,"Observado") | G15: =COUNTIFS(Checklist!$A$5:$A$137,"11.*",Checklist!$J$5:$J$137,1,Checklist!$E$5:$E$137,"Pendiente") | H15: =IF(C15=0,IF(I15>0,1,0),D15/C15) | I15: =COUNTIFS(Checklist!$A$5:$A$137,"11.*",Checklist!$J$5:$J$137,1,Checklist!$E$5:$E$137,"No aplica")
A16: 12 | B16: Evaluación Curricular | C16: =COUNTIFS(Checklist!$A$5:$A$137,"12.*",Checklist!$J$5:$J$137,1,Checklist!$E$5:$E$137,"<>No aplica") | D16: =COUNTIFS(Checklist!$A$5:$A$137,"12.*",Checklist!$J$5:$J$137,1,Checklist!$E$5:$E$137,"Entregado") | E16: =COUNTIFS(Checklist!$A$5:$A$137,"12.*",Checklist!$J$5:$J$137,1,Checklist!$E$5:$E$137,"Parcial") | F16: =COUNTIFS(Checklist!$A$5:$A$137,"12.*",Checklist!$J$5:$J$137,1,Checklist!$E$5:$E$137,"Observado") | G16: =COUNTIFS(Checklist!$A$5:$A$137,"12.*",Checklist!$J$5:$J$137,1,Checklist!$E$5:$E$137,"Pendiente") | H16: =IF(C16=0,IF(I16>0,1,0),D16/C16) | I16: =COUNTIFS(Checklist!$A$5:$A$137,"12.*",Checklist!$J$5:$J$137,1,Checklist!$E$5:$E$137,"No aplica")
A17: 13 | B17: Reglamentación | C17: =COUNTIFS(Checklist!$A$5:$A$137,"13.*",Checklist!$J$5:$J$137,1,Checklist!$E$5:$E$137,"<>No aplica") | D17: =COUNTIFS(Checklist!$A$5:$A$137,"13.*",Checklist!$J$5:$J$137,1,Checklist!$E$5:$E$137,"Entregado") | E17: =COUNTIFS(Checklist!$A$5:$A$137,"13.*",Checklist!$J$5:$J$137,1,Checklist!$E$5:$E$137,"Parcial") | F17: =COUNTIFS(Checklist!$A$5:$A$137,"13.*",Checklist!$J$5:$J$137,1,Checklist!$E$5:$E$137,"Observado") | G17: =COUNTIFS(Checklist!$A$5:$A$137,"13.*",Checklist!$J$5:$J$137,1,Checklist!$E$5:$E$137,"Pendiente") | H17: =IF(C17=0,IF(I17>0,1,0),D17/C17) | I17: =COUNTIFS(Checklist!$A$5:$A$137,"13.*",Checklist!$J$5:$J$137,1,Checklist!$E$5:$E$137,"No aplica")
A18: 14 | B18: Infraestructura y equipamiento | C18: =COUNTIFS(Checklist!$A$5:$A$137,"14.*",Checklist!$J$5:$J$137,1,Checklist!$E$5:$E$137,"<>No aplica") | D18: =COUNTIFS(Checklist!$A$5:$A$137,"14.*",Checklist!$J$5:$J$137,1,Checklist!$E$5:$E$137,"Entregado") | E18: =COUNTIFS(Checklist!$A$5:$A$137,"14.*",Checklist!$J$5:$J$137,1,Checklist!$E$5:$E$137,"Parcial") | F18: =COUNTIFS(Checklist!$A$5:$A$137,"14.*",Checklist!$J$5:$J$137,1,Checklist!$E$5:$E$137,"Observado") | G18: =COUNTIFS(Checklist!$A$5:$A$137,"14.*",Checklist!$J$5:$J$137,1,Checklist!$E$5:$E$137,"Pendiente") | H18: =IF(C18=0,IF(I18>0,1,0),D18/C18) | I18: =COUNTIFS(Checklist!$A$5:$A$137,"14.*",Checklist!$J$5:$J$137,1,Checklist!$E$5:$E$137,"No aplica")
A19: 15 | B19: Mobiliario, equipamiento y materiales | C19: =COUNTIFS(Checklist!$A$5:$A$137,"15.*",Checklist!$J$5:$J$137,1,Checklist!$E$5:$E$137,"<>No aplica") | D19: =COUNTIFS(Checklist!$A$5:$A$137,"15.*",Checklist!$J$5:$J$137,1,Checklist!$E$5:$E$137,"Entregado") | E19: =COUNTIFS(Checklist!$A$5:$A$137,"15.*",Checklist!$J$5:$J$137,1,Checklist!$E$5:$E$137,"Parcial") | F19: =COUNTIFS(Checklist!$A$5:$A$137,"15.*",Checklist!$J$5:$J$137,1,Checklist!$E$5:$E$137,"Observado") | G19: =COUNTIFS(Checklist!$A$5:$A$137,"15.*",Checklist!$J$5:$J$137,1,Checklist!$E$5:$E$137,"Pendiente") | H19: =IF(C19=0,IF(I19>0,1,0),D19/C19) | I19: =COUNTIFS(Checklist!$A$5:$A$137,"15.*",Checklist!$J$5:$J$137,1,Checklist!$E$5:$E$137,"No aplica")
A20: 16 | B20: Disposiciones de ejecución | C20: =COUNTIFS(Checklist!$A$5:$A$137,"16.*",Checklist!$J$5:$J$137,1,Checklist!$E$5:$E$137,"<>No aplica") | D20: =COUNTIFS(Checklist!$A$5:$A$137,"16.*",Checklist!$J$5:$J$137,1,Checklist!$E$5:$E$137,"Entregado") | E20: =COUNTIFS(Checklist!$A$5:$A$137,"16.*",Checklist!$J$5:$J$137,1,Checklist!$E$5:$E$137,"Parcial") | F20: =COUNTIFS(Checklist!$A$5:$A$137,"16.*",Checklist!$J$5:$J$137,1,Checklist!$E$5:$E$137,"Observado") | G20: =COUNTIFS(Checklist!$A$5:$A$137,"16.*",Checklist!$J$5:$J$137,1,Checklist!$E$5:$E$137,"Pendiente") | H20: =IF(C20=0,IF(I20>0,1,0),D20/C20) | I20: =COUNTIFS(Checklist!$A$5:$A$137,"16.*",Checklist!$J$5:$J$137,1,Checklist!$E$5:$E$137,"No aplica")
B21: TOTAL | C21: =SUM(C5:C20) | D21: =SUM(D5:D20) | E21: =SUM(E5:E20) | F21: =SUM(F5:F20) | G21: =SUM(G5:G20) | H21: =IF(C21=0,IF(I21>0,1,0),D21/C21) | I21: =SUM(I5:I20)
