Workbook

Sheet Checklist
A1: Rediseño Curricular 2026 · Control de entregas de las subcomisiones
A2: Carrera de Contaduría Pública · Facultad de Ciencias Económicas y Financieras · Universidad Mayor de San Andrés
A4: Código | B4: Punto del índice | C4: Responsable docente | D4: Responsable estudiantil | E4: Estado | F4: Fecha de recepción | G4: Formato recibido | H4: Adaptado al formato | I4: Observaciones | J4: Entregable
A5: 1. | B5: Identificación del programa/carrera | C5: Edwin Gutiérrez Zapana | D5: Alarcon Pablo Alejandro | E5: =IF(SUMPRODUCT(($J$6:$J$18=1)*($E$6:$E$18="Entregado"))=SUMPRODUCT(($J$6:$J$18=1)*1),"Completo",IF(SUMPRODUCT(($J$6:$J$18=1)*($E$6:$E$18="Pendiente"))=SUMPRODUCT(($J$6:$J$18=1)*1),"Pendiente","En proceso")) | F5: =SUMPRODUCT(($J$6:$J$18=1)*($E$6:$E$18="Entregado"))&" de "&SUMPRODUCT(($J$6:$J$18=1)*1) | G5: — | H5: — | J5: 0
A6: 1.1 | B6: Facultad | C6: Edwin Gutiérrez Zapana | D6: Alarcon Pablo Alejandro | E6: Pendiente | H6: No | J6: 1
A7: 1.2 | B7: Programa/carrera | C7: Edwin Gutiérrez Zapana | D7: Alarcon Pablo Alejandro | E7: Pendiente | H7: No | J7: 1
A8: 1.3 | B8: Fecha de creación y Resolución HCU | C8: Edwin Gutiérrez Zapana | D8: Alarcon Pablo Alejandro | E8: Pendiente | H8: No | J8: 1
A9: 1.4 | B9: Resolución(es) HCU que aprobaron planes de estudio anteriores | C9: Edwin Gutiérrez Zapana | D9: Alarcon Pablo Alejandro | E9: Pendiente | H9: No | J9: 1
A10: 1.5 | B10: Grado académico terminal | C10: Edwin Gutiérrez Zapana | D10: Alarcon Pablo Alejandro | E10: Pendiente | H10: No | J10: 1
A11: 1.6 | B11: Grado(s) académico(s) intermedio(s) | C11: Edwin Gutiérrez Zapana | D11: Alarcon Pablo Alejandro | E11: Pendiente | H11: No | J11: 1
A12: 1.7 | B12: Sede(s) | C12: Edwin Gutiérrez Zapana | D12: Alarcon Pablo Alejandro | E12: Pendiente | H12: No | J12: 1
A13: 1.8 | B13: Diploma académico terminal | C13: Edwin Gutiérrez Zapana | D13: Alarcon Pablo Alejandro | E13: Pendiente | H13: No | J13: 1
A14: 1.9 | B14: Diploma(s) académico(s) intermedio(s) | C14: Edwin Gutiérrez Zapana | D14: Alarcon Pablo Alejandro | E14: Pendiente | H14: No | J14: 1
A15: 1.10 | B15: Título Profesional | C15: Edwin Gutiérrez Zapana | D15: Alarcon Pablo Alejandro | E15: Pendiente | H15: No | J15: 1
A16: 1.11 | B16: Título(s) profesional(es) intermedio(s) | C16: Edwin Gutiérrez Zapana | D16: Alarcon Pablo Alejandro | E16: Pendiente | H16: No | J16: 1
A17: 1.12 | B17: Modalidad(es) de docencia | C17: Edwin Gutiérrez Zapana | D17: Alarcon Pablo Alejandro | E17: Pendiente | H17: No | J17: 1
A18: 1.13 | B18: Otras características | C18: Edwin Gutiérrez Zapana | D18: Alarcon Pablo Alejandro | E18: Pendiente | H18: No | J18: 1
A19: 2. | B19: Antecedentes | C19: Sin asignar | D19: Sin asignar | E19: =IF(SUMPRODUCT(($J$20:$J$26=1)*($E$20:$E$26="Entregado"))=SUMPRODUCT(($J$20:$J$26=1)*1),"Completo",IF(SUMPRODUCT(($J$20:$J$26=1)*($E$20:$E$26="Pendiente"))=SUMPRODUCT(($J$20:$J$26=1)*1),"Pendiente","En proceso")) | F19: =SUMPRODUCT(($J$20:$J$26=1)*($E$20:$E$26="Entregado"))&" de "&SUMPRODUCT(($J$20:$J$26=1)*1) | G19: — | H19: — | J19: 0
A20: 2.1 | B20: Datos generales del programa/carrera | C20: Sin asignar | D20: Sin asignar | E20: Pendiente | H20: No | J20: 1
A21: 2.2 | B21: Misión, visión de la carrera | C21: Sin asignar | D21: Sin asignar | E21: Entregado | F21: 46306 | G21: Word | H21: Sí | I21: Documento Misión, Visión y Perfil Profesional 2026 | J21: 1
A22: 2.3 | B22: Plan de desarrollo de la carrera | C22: Sin asignar | D22: Sin asignar | E22: Pendiente | H22: No | J22: 1
A23: 2.4 | B23: Objetivos del programa/carrera | C23: Sin asignar | D23: Sin asignar | E23: Entregado | F23: 46306 | G23: Word | H23: Sí | I23: Documento Misión, Visión y Perfil Profesional 2026; también en Documento 04 Plan de Estudios 2026 | J23: 1
A24: 2.5 | B24: Características del programa/carrera | C24: Sin asignar | D24: Sin asignar | E24: Pendiente | H24: No | J24: 1
A25: 2.6 | B25: Organigrama del programa/carrera | C25: Sin asignar | D25: Sin asignar | E25: Pendiente | H25: No | J25: 1
A26: 2.7 | B26: Estadísticas del programa/carrera | C26: Sin asignar | D26: Sin asignar | E26: Pendiente | H26: No | J26: 1
A27: 3. | B27: Justificación de la innovación curricular (solo para niveles de diseño, rediseño y ajustes) | C27: Alberto Mendoza Mendoza | D27: Ayrton Javier Quisbert Fernandez | E27: =IF(SUMPRODUCT(($J$28:$J$32=1)*($E$28:$E$32="Entregado"))=SUMPRODUCT(($J$28:$J$32=1)*1),"Completo",IF(SUMPRODUCT(($J$28:$J$32=1)*($E$28:$E$32="Pendiente"))=SUMPRODUCT(($J$28:$J$32=1)*1),"Pendiente","En proceso")) | F27: =SUMPRODUCT(($J$28:$J$32=1)*($E$28:$E$32="Entregado"))&" de "&SUMPRODUCT(($J$28:$J$32=1)*1) | G27: — | H27: — | J27: 0
A28: 3.1 | B28: Análisis de resultados obtenidos con anteriores planes de estudio (descripción estadística y cualitativa) | C28: Alberto Mendoza Mendoza | D28: Ayrton Javier Quisbert Fernandez | E28: Pendiente | H28: No | J28: 1
A29: 3.2 | B29: Análisis de las políticas y normas (internacionales, nacionales y universitarias) | C29: Alberto Mendoza Mendoza | D29: Ayrton Javier Quisbert Fernandez | E29: Entregado | F29: 46307 | G29: Word | H29: Sí | I29: Documento 04 Plan de Estudios 2026 | J29: 1
A30: 3.3 | B30: Análisis del contexto económico, estudio de mercado laboral e inserción laboral | C30: Alberto Mendoza Mendoza | D30: Ayrton Javier Quisbert Fernandez | E30: Pendiente | H30: No | J30: 1
A31: 3.4 | B31: Análisis del contexto de cambios y tendencias de la ciencia y tecnología a nivel global | C31: Humberto Quintanilla Muñoz | D31: Beymar Adalid Paucara Marquez | E31: Pendiente | H31: No | J31: 1
A32: 3.5 | B32: Contextualización de la oferta curricular en la realidad nacional e internacional | C32: Humberto Quintanilla Muñoz | D32: Beymar Adalid Paucara Marquez | E32: Entregado | F32: 46307 | G32: Word | H32: Sí | I32: Documento 04 Plan de Estudios 2026 | J32: 1
A33: 4. | B33: Aspectos académicos | C33: Freddy Huanca Mamani | D33: Katherin Fabiola Ali Quispe | E33: =IF(SUMPRODUCT(($J$34:$J$71=1)*($E$34:$E$71="Entregado"))=SUMPRODUCT(($J$34:$J$71=1)*1),"Completo",IF(SUMPRODUCT(($J$34:$J$71=1)*($E$34:$E$71="Pendiente"))=SUMPRODUCT(($J$34:$J$71=1)*1),"Pendiente","En proceso")) | F33: =SUMPRODUCT(($J$34:$J$71=1)*($E$34:$E$71="Entregado"))&" de "&SUMPRODUCT(($J$34:$J$71=1)*1) | G33: — | H33: — | J33: 0
A34: 4.1 | B34: Fundamentos curriculares | C34: Freddy Huanca Mamani | D34: Katherin Fabiola Ali Quispe | E34: =IF(SUMPRODUCT(($J$35:$J$39=1)*($E$35:$E$39="Entregado"))=SUMPRODUCT(($J$35:$J$39=1)*1),"Completo",IF(SUMPRODUCT(($J$35:$J$39=1)*($E$35:$E$39="Pendiente"))=SUMPRODUCT(($J$35:$J$39=1)*1),"Pendiente","En proceso")) | F34: =SUMPRODUCT(($J$35:$J$39=1)*($E$35:$E$39="Entregado"))&" de "&SUMPRODUCT(($J$35:$J$39=1)*1) | G34: — | H34: — | J34: 0
A35: 4.1.1 | B35: Fundamentos epistemológicos | C35: Freddy Huanca Mamani | D35: Katherin Fabiola Ali Quispe | E35: Entregado | F35: 46307 | G35: Word | H35: Sí | I35: Documento 04 Plan de Estudios 2026 | J35: 1
A36: 4.1.2 | B36: Fundamentos sociológicos antropológicos | C36: Freddy Huanca Mamani | D36: Katherin Fabiola Ali Quispe | E36: Entregado | F36: 46307 | G36: Word | H36: Sí | I36: Documento 04 Plan de Estudios 2026 | J36: 1
A37: 4.1.3 | B37: Fundamentos psicológicos | C37: Jorge Cespedes Esteves | D37: Taiz Alejandra Cano Chuyma | E37: Pendiente | H37: No | J37: 1
A38: 4.1.4 | B38: Fundamentos educativos | C38: Jorge Cespedes Esteves | D38: Taiz Alejandra Cano Chuyma | E38: Entregado | F38: 46307 | G38: Word | H38: Sí | I38: Documento 04 Plan de Estudios 2026 | J38: 1
A39: 4.1.5 | B39: Fundamentos axiológicos | C39: Jorge Cespedes Esteves | D39: Taiz Alejandra Cano Chuyma | E39: Entregado | F39: 46307 | G39: Word | H39: Sí | I39: Propuesta en Contenido extra: Valores, por confirmar; Documento 04 Plan de Estudios 2026 | J39: 1
A40: 4.2 | B40: Referentes disciplinares | C40: Hinojosa | D40: Melany Sarah Chavez Condori | E40: =IF(SUMPRODUCT(($J$41:$J$47=1)*($E$41:$E$47="Entregado"))=SUMPRODUCT(($J$41:$J$47=1)*1),"Completo",IF(SUMPRODUCT(($J$41:$J$47=1)*($E$41:$E$47="Pendiente"))=SUMPRODUCT(($J$41:$J$47=1)*1),"Pendiente","En proceso")) | F40: =SUMPRODUCT(($J$41:$J$47=1)*($E$41:$E$47="Entregado"))&" de "&SUMPRODUCT(($J$41:$J$47=1)*1) | G40: — | H40: — | J40: 0
A41: 4.2.1 | B41: Problemas que serán abordados por el profesional | C41: Hinojosa | D41: Melany Sarah Chavez Condori | E41: Pendiente | H41: No | I41: Propuesta en Contenido extra: Necesidades de formación, por confirmar | J41: 1
...

Sheet Resumen
A1: Resumen de avance por punto
A2: Se calcula solo con los ítems entregables de la hoja Checklist.
A4: Punto | B4: Título | C4: Ítems | D4: Entregados | E4: Parciales | F4: Observados | G4: Pendientes | H4: Avance
A5: 1 | B5: Identificación del programa/carrera | C5: =COUNTIFS(Checklist!$A$5:$A$137,"1.*",Checklist!$J$5:$J$137,1) | D5: =COUNTIFS(Checklist!$A$5:$A$137,"1.*",Checklist!$J$5:$J$137,1,Checklist!$E$5:$E$137,"Entregado") | E5: =COUNTIFS(Checklist!$A$5:$A$137,"1.*",Checklist!$J$5:$J$137,1,Checklist!$E$5:$E$137,"Parcial") | F5: =COUNTIFS(Checklist!$A$5:$A$137,"1.*",Checklist!$J$5:$J$137,1,Checklist!$E$5:$E$137,"Observado") | G5: =COUNTIFS(Checklist!$A$5:$A$137,"1.*",Checklist!$J$5:$J$137,1,Checklist!$E$5:$E$137,"Pendiente") | H5: =IF(C5=0,0,D5/C5)
A6: 2 | B6: Antecedentes | C6: =COUNTIFS(Checklist!$A$5:$A$137,"2.*",Checklist!$J$5:$J$137,1) | D6: =COUNTIFS(Checklist!$A$5:$A$137,"2.*",Checklist!$J$5:$J$137,1,Checklist!$E$5:$E$137,"Entregado") | E6: =COUNTIFS(Checklist!$A$5:$A$137,"2.*",Checklist!$J$5:$J$137,1,Checklist!$E$5:$E$137,"Parcial") | F6: =COUNTIFS(Checklist!$A$5:$A$137,"2.*",Checklist!$J$5:$J$137,1,Checklist!$E$5:$E$137,"Observado") | G6: =COUNTIFS(Checklist!$A$5:$A$137,"2.*",Checklist!$J$5:$J$137,1,Checklist!$E$5:$E$137,"Pendiente") | H6: =IF(C6=0,0,D6/C6)
A7: 3 | B7: Justificación de la innovación curricular (solo para niveles de diseño, rediseño y ajustes) | C7: =COUNTIFS(Checklist!$A$5:$A$137,"3.*",Checklist!$J$5:$J$137,1) | D7: =COUNTIFS(Checklist!$A$5:$A$137,"3.*",Checklist!$J$5:$J$137,1,Checklist!$E$5:$E$137,"Entregado") | E7: =COUNTIFS(Checklist!$A$5:$A$137,"3.*",Checklist!$J$5:$J$137,1,Checklist!$E$5:$E$137,"Parcial") | F7: =COUNTIFS(Checklist!$A$5:$A$137,"3.*",Checklist!$J$5:$J$137,1,Checklist!$E$5:$E$137,"Observado") | G7: =COUNTIFS(Checklist!$A$5:$A$137,"3.*",Checklist!$J$5:$J$137,1,Checklist!$E$5:$E$137,"Pendiente") | H7: =IF(C7=0,0,D7/C7)
A8: 4 | B8: Aspectos académicos | C8: =COUNTIFS(Checklist!$A$5:$A$137,"4.*",Checklist!$J$5:$J$137,1) | D8: =COUNTIFS(Checklist!$A$5:$A$137,"4.*",Checklist!$J$5:$J$137,1,Checklist!$E$5:$E$137,"Entregado") | E8: =COUNTIFS(Checklist!$A$5:$A$137,"4.*",Checklist!$J$5:$J$137,1,Checklist!$E$5:$E$137,"Parcial") | F8: =COUNTIFS(Checklist!$A$5:$A$137,"4.*",Checklist!$J$5:$J$137,1,Checklist!$E$5:$E$137,"Observado") | G8: =COUNTIFS(Checklist!$A$5:$A$137,"4.*",Checklist!$J$5:$J$137,1,Checklist!$E$5:$E$137,"Pendiente") | H8: =IF(C8=0,0,D8/C8)
A9: 5 | B9: Admisión, promoción y graduación | C9: =COUNTIFS(Checklist!$A$5:$A$137,"5.*",Checklist!$J$5:$J$137,1) | D9: =COUNTIFS(Checklist!$A$5:$A$137,"5.*",Checklist!$J$5:$J$137,1,Checklist!$E$5:$E$137,"Entregado") | E9: =COUNTIFS(Checklist!$A$5:$A$137,"5.*",Checklist!$J$5:$J$137,1,Checklist!$E$5:$E$137,"Parcial") | F9: =COUNTIFS(Checklist!$A$5:$A$137,"5.*",Checklist!$J$5:$J$137,1,Checklist!$E$5:$E$137,"Observado") | G9: =COUNTIFS(Checklist!$A$5:$A$137,"5.*",Checklist!$J$5:$J$137,1,Checklist!$E$5:$E$137,"Pendiente") | H9: =IF(C9=0,0,D9/C9)
A10: 6 | B10: Investigación (articulada con los institutos o unidades de investigación relacionados con la carrera/programa) | C10: =COUNTIFS(Checklist!$A$5:$A$137,"6.*",Checklist!$J$5:$J$137,1) | D10: =COUNTIFS(Checklist!$A$5:$A$137,"6.*",Checklist!$J$5:$J$137,1,Checklist!$E$5:$E$137,"Entregado") | E10: =COUNTIFS(Checklist!$A$5:$A$137,"6.*",Checklist!$J$5:$J$137,1,Checklist!$E$5:$E$137,"Parcial") | F10: =COUNTIFS(Checklist!$A$5:$A$137,"6.*",Checklist!$J$5:$J$137,1,Checklist!$E$5:$E$137,"Observado") | G10: =COUNTIFS(Checklist!$A$5:$A$137,"6.*",Checklist!$J$5:$J$137,1,Checklist!$E$5:$E$137,"Pendiente") | H10: =IF(C10=0,0,D10/C10)
A11: 7 | B11: Interacción social y extensión universitaria | C11: =COUNTIFS(Checklist!$A$5:$A$137,"7.*",Checklist!$J$5:$J$137,1) | D11: =COUNTIFS(Checklist!$A$5:$A$137,"7.*",Checklist!$J$5:$J$137,1,Checklist!$E$5:$E$137,"Entregado") | E11: =COUNTIFS(Checklist!$A$5:$A$137,"7.*",Checklist!$J$5:$J$137,1,Checklist!$E$5:$E$137,"Parcial") | F11: =COUNTIFS(Checklist!$A$5:$A$137,"7.*",Checklist!$J$5:$J$137,1,Checklist!$E$5:$E$137,"Observado") | G11: =COUNTIFS(Checklist!$A$5:$A$137,"7.*",Checklist!$J$5:$J$137,1,Checklist!$E$5:$E$137,"Pendiente") | H11: =IF(C11=0,0,D11/C11)
A12: 8 | B12: Organización del proceso curricular | C12: =COUNTIFS(Checklist!$A$5:$A$137,"8.*",Checklist!$J$5:$J$137,1) | D12: =COUNTIFS(Checklist!$A$5:$A$137,"8.*",Checklist!$J$5:$J$137,1,Checklist!$E$5:$E$137,"Entregado") | E12: =COUNTIFS(Checklist!$A$5:$A$137,"8.*",Checklist!$J$5:$J$137,1,Checklist!$E$5:$E$137,"Parcial") | F12: =COUNTIFS(Checklist!$A$5:$A$137,"8.*",Checklist!$J$5:$J$137,1,Checklist!$E$5:$E$137,"Observado") | G12: =COUNTIFS(Checklist!$A$5:$A$137,"8.*",Checklist!$J$5:$J$137,1,Checklist!$E$5:$E$137,"Pendiente") | H12: =IF(C12=0,0,D12/C12)
A13: 9 | B13: Material Bibliográfico | C13: =COUNTIFS(Checklist!$A$5:$A$137,"9.*",Checklist!$J$5:$J$137,1) | D13: =COUNTIFS(Checklist!$A$5:$A$137,"9.*",Checklist!$J$5:$J$137,1,Checklist!$E$5:$E$137,"Entregado") | E13: =COUNTIFS(Checklist!$A$5:$A$137,"9.*",Checklist!$J$5:$J$137,1,Checklist!$E$5:$E$137,"Parcial") | F13: =COUNTIFS(Checklist!$A$5:$A$137,"9.*",Checklist!$J$5:$J$137,1,Checklist!$E$5:$E$137,"Observado") | G13: =COUNTIFS(Checklist!$A$5:$A$137,"9.*",Checklist!$J$5:$J$137,1,Checklist!$E$5:$E$137,"Pendiente") | H13: =IF(C13=0,0,D13/C13)
A14: 10 | B14: Recursos educativos | C14: =COUNTIFS(Checklist!$A$5:$A$137,"10.*",Checklist!$J$5:$J$137,1) | D14: =COUNTIFS(Checklist!$A$5:$A$137,"10.*",Checklist!$J$5:$J$137,1,Checklist!$E$5:$E$137,"Entregado") | E14: =COUNTIFS(Checklist!$A$5:$A$137,"10.*",Checklist!$J$5:$J$137,1,Checklist!$E$5:$E$137,"Parcial") | F14: =COUNTIFS(Checklist!$A$5:$A$137,"10.*",Checklist!$J$5:$J$137,1,Checklist!$E$5:$E$137,"Observado") | G14: =COUNTIFS(Checklist!$A$5:$A$137,"10.*",Checklist!$J$5:$J$137,1,Checklist!$E$5:$E$137,"Pendiente") | H14: =IF(C14=0,0,D14/C14)
A15: 11 | B15: Implementación del proyecto curricular | C15: =COUNTIFS(Checklist!$A$5:$A$137,"11.*",Checklist!$J$5:$J$137,1) | D15: =COUNTIFS(Checklist!$A$5:$A$137,"11.*",Checklist!$J$5:$J$137,1,Checklist!$E$5:$E$137,"Entregado") | E15: =COUNTIFS(Checklist!$A$5:$A$137,"11.*",Checklist!$J$5:$J$137,1,Checklist!$E$5:$E$137,"Parcial") | F15: =COUNTIFS(Checklist!$A$5:$A$137,"11.*",Checklist!$J$5:$J$137,1,Checklist!$E$5:$E$137,"Observado") | G15: =COUNTIFS(Checklist!$A$5:$A$137,"11.*",Checklist!$J$5:$J$137,1,Checklist!$E$5:$E$137,"Pendiente") | H15: =IF(C15=0,0,D15/C15)
A16: 12 | B16: Evaluación Curricular | C16: =COUNTIFS(Checklist!$A$5:$A$137,"12.*",Checklist!$J$5:$J$137,1) | D16: =COUNTIFS(Checklist!$A$5:$A$137,"12.*",Checklist!$J$5:$J$137,1,Checklist!$E$5:$E$137,"Entregado") | E16: =COUNTIFS(Checklist!$A$5:$A$137,"12.*",Checklist!$J$5:$J$137,1,Checklist!$E$5:$E$137,"Parcial") | F16: =COUNTIFS(Checklist!$A$5:$A$137,"12.*",Checklist!$J$5:$J$137,1,Checklist!$E$5:$E$137,"Observado") | G16: =COUNTIFS(Checklist!$A$5:$A$137,"12.*",Checklist!$J$5:$J$137,1,Checklist!$E$5:$E$137,"Pendiente") | H16: =IF(C16=0,0,D16/C16)
A17: 13 | B17: Reglamentación | C17: =COUNTIFS(Checklist!$A$5:$A$137,"13.*",Checklist!$J$5:$J$137,1) | D17: =COUNTIFS(Checklist!$A$5:$A$137,"13.*",Checklist!$J$5:$J$137,1,Checklist!$E$5:$E$137,"Entregado") | E17: =COUNTIFS(Checklist!$A$5:$A$137,"13.*",Checklist!$J$5:$J$137,1,Checklist!$E$5:$E$137,"Parcial") | F17: =COUNTIFS(Checklist!$A$5:$A$137,"13.*",Checklist!$J$5:$J$137,1,Checklist!$E$5:$E$137,"Observado") | G17: =COUNTIFS(Checklist!$A$5:$A$137,"13.*",Checklist!$J$5:$J$137,1,Checklist!$E$5:$E$137,"Pendiente") | H17: =IF(C17=0,0,D17/C17)
A18: 14 | B18: Infraestructura y equipamiento | C18: =COUNTIFS(Checklist!$A$5:$A$137,"14.*",Checklist!$J$5:$J$137,1) | D18: =COUNTIFS(Checklist!$A$5:$A$137,"14.*",Checklist!$J$5:$J$137,1,Checklist!$E$5:$E$137,"Entregado") | E18: =COUNTIFS(Checklist!$A$5:$A$137,"14.*",Checklist!$J$5:$J$137,1,Checklist!$E$5:$E$137,"Parcial") | F18: =COUNTIFS(Checklist!$A$5:$A$137,"14.*",Checklist!$J$5:$J$137,1,Checklist!$E$5:$E$137,"Observado") | G18: =COUNTIFS(Checklist!$A$5:$A$137,"14.*",Checklist!$J$5:$J$137,1,Checklist!$E$5:$E$137,"Pendiente") | H18: =IF(C18=0,0,D18/C18)
A19: 15 | B19: Mobiliario, equipamiento y materiales | C19: =COUNTIFS(Checklist!$A$5:$A$137,"15.*",Checklist!$J$5:$J$137,1) | D19: =COUNTIFS(Checklist!$A$5:$A$137,"15.*",Checklist!$J$5:$J$137,1,Checklist!$E$5:$E$137,"Entregado") | E19: =COUNTIFS(Checklist!$A$5:$A$137,"15.*",Checklist!$J$5:$J$137,1,Checklist!$E$5:$E$137,"Parcial") | F19: =COUNTIFS(Checklist!$A$5:$A$137,"15.*",Checklist!$J$5:$J$137,1,Checklist!$E$5:$E$137,"Observado") | G19: =COUNTIFS(Checklist!$A$5:$A$137,"15.*",Checklist!$J$5:$J$137,1,Checklist!$E$5:$E$137,"Pendiente") | H19: =IF(C19=0,0,D19/C19)
A20: 16 | B20: Disposiciones de ejecución | C20: =COUNTIFS(Checklist!$A$5:$A$137,"16.*",Checklist!$J$5:$J$137,1) | D20: =COUNTIFS(Checklist!$A$5:$A$137,"16.*",Checklist!$J$5:$J$137,1,Checklist!$E$5:$E$137,"Entregado") | E20: =COUNTIFS(Checklist!$A$5:$A$137,"16.*",Checklist!$J$5:$J$137,1,Checklist!$E$5:$E$137,"Parcial") | F20: =COUNTIFS(Checklist!$A$5:$A$137,"16.*",Checklist!$J$5:$J$137,1,Checklist!$E$5:$E$137,"Observado") | G20: =COUNTIFS(Checklist!$A$5:$A$137,"16.*",Checklist!$J$5:$J$137,1,Checklist!$E$5:$E$137,"Pendiente") | H20: =IF(C20=0,0,D20/C20)
B21: TOTAL | C21: =SUM(C5:C20) | D21: =SUM(D5:D20) | E21: =SUM(E5:E20) | F21: =SUM(F5:F20) | G21: =SUM(G5:G20) | H21: =IF(C21=0,0,D21/C21)
